<?xml version="1.0" ?>
<!-- =================================================================================== -->
<!-- |    This document was autogenerated by xacro from ./src/my_robot_description/urdf/my_robot.xacro | -->
<!-- |    EDITING THIS FILE BY HAND IS NOT RECOMMENDED                                 | -->
<!-- =================================================================================== -->
<robot name="my_robot">
  <!-- TODO : fix wheel inertia -->
  <!-- shaft Z offset referenced at the botton of the case -->
  <material name="white">
    <color rgba="0.8 0.8 0.8 1"/>
  </material>
  <material name="black">
    <color rgba="0.1 0.1 0.1 1"/>
  </material>
  <material name="red">
    <color rgba="0.8 0.1 0.1 1"/>
  </material>
  <!-- ****************** ROBOT BASE FOOTPRINT (Z=0, center of rotation) ***************************  -->
  <link name="base_footprint"/>
  <joint name="base_joint" type="fixed">
    <parent link="base_footprint"/>
    <child link="case"/>
    <origin rpy="0 0 0" xyz="-0.15 0 0.125"/>
  </joint>
  <!-- ********************** ROBOT CASE *********************************  -->
  <link name="case">
    <collision>
      <origin rpy="0 0 0" xyz="0 0 0"/>
      <geometry>
        <box size="0.44 0.36 0.16"/>
      </geometry>
    </collision>
    <visual>
      <origin rpy="0 0 0" xyz="0 0 0"/>
      <geometry>
        <box size="0.44 0.36 0.16"/>
      </geometry>
      <material name="white"/>
    </visual>
    <inertial>
      <origin rpy="0 0 0" xyz="0 0 0"/>
      <mass value="2.0"/>
      <inertia ixx="0.025866666666666666" ixy="0.0" ixz="0.0" iyy="0.036533333333333334" iyz="0.0" izz="0.05386666666666666"/>
    </inertial>
  </link>
  <!-- ****************** ROBOT WHEELS ***************************  -->
  <joint name="left_wheel_joint" type="continuous">
    <parent link="case"/>
    <child link="left_wheel"/>
    <origin rpy="0 0 0" xyz="0.15 0.265 -0.04"/>
    <axis xyz="0 1 0"/>
    <dynamics damping="0.2"/>
  </joint>
  <!-- left wheel Link -->
  <link name="left_wheel">
    <collision>
      <origin rpy="1.5707963267948966 0 0" xyz="0 0 0"/>
      <geometry>
        <cylinder length="0.05" radius="0.085"/>
      </geometry>
    </collision>
    <visual>
      <origin rpy="1.5707963267948966 0 0" xyz="0 0 0"/>
      <geometry>
        <cylinder length="0.05" radius="0.085"/>
      </geometry>
      <material name="black"/>
    </visual>
    <inertial>
      <origin rpy="0 0 0" xyz="0 0 0"/>
      <mass value="2.5"/>
      <inertia ixx="0.005036458333333334" ixy="0" ixz="0" iyy="0.009031250000000001" iyz="0" izz="0.005036458333333334"/>
    </inertial>
  </link>
  <joint name="right_wheel_joint" type="continuous">
    <parent link="case"/>
    <child link="right_wheel"/>
    <origin rpy="0 0 0" xyz="0.15 -0.265 -0.04"/>
    <axis xyz="0 1 0"/>
    <dynamics damping="0.2"/>
  </joint>
  <!-- right wheel Link -->
  <link name="right_wheel">
    <collision>
      <origin rpy="1.5707963267948966 0 0" xyz="0 0 0"/>
      <geometry>
        <cylinder length="0.05" radius="0.085"/>
      </geometry>
    </collision>
    <visual>
      <origin rpy="1.5707963267948966 0 0" xyz="0 0 0"/>
      <geometry>
        <cylinder length="0.05" radius="0.085"/>
      </geometry>
      <material name="black"/>
    </visual>
    <inertial>
      <origin rpy="0 0 0" xyz="0 0 0"/>
      <mass value="2.5"/>
      <inertia ixx="0.005036458333333334" ixy="0" ixz="0" iyy="0.009031250000000001" iyz="0" izz="0.005036458333333334"/>
    </inertial>
  </link>
  <joint name="caster_wheel_joint" type="fixed">
    <parent link="case"/>
    <child link="caster_wheel"/>
    <origin rpy="0 0 0" xyz="-0.15 0 -0.1"/>
  </joint>
  <!-- caster wheel Link -->
  <link name="caster_wheel">
    <collision>
      <origin rpy="0 0 0" xyz="0 0 0"/>
      <geometry>
        <sphere radius="0.025"/>
      </geometry>
    </collision>
    <visual>
      <origin rpy="0 0 0" xyz="0 0 0"/>
      <geometry>
        <sphere radius="0.025"/>
      </geometry>
      <material name="black"/>
    </visual>
    <inertial>
      <origin rpy="0 0 0" xyz="0 0 0"/>
      <mass value="0.1"/>
      <inertia ixx="2.500000000000001e-05" ixy="0.0" ixz="0.0" iyy="2.500000000000001e-05" iyz="0.0" izz="2.500000000000001e-05"/>
    </inertial>
  </link>
  <!-- ****************** LASER SENSOR ***************************  -->
  <!-- laser joint -->
  <joint name="laser_joint" type="fixed">
    <parent link="case"/>
    <child link="laser"/>
    <origin rpy="0 0 0" xyz="0.180 0.0 0.115 "/>
  </joint>
  <!-- laser Link -->
  <link name="laser">
    <collision>
      <origin rpy="0 0 0" xyz="0 0 0"/>
      <geometry>
        <box size="0.05 0.05 0.07 "/>
      </geometry>
    </collision>
    <visual>
      <origin rpy="0 0 0" xyz="0 0 0"/>
      <geometry>
        <box size="0.05 0.05 0.07 "/>
      </geometry>
      <material name="red"/>
    </visual>
    <inertial>
      <origin rpy="0 0 0" xyz="0 0 0"/>
      <mass value="0.13"/>
      <inertia ixx="8.016666666666669e-05" ixy="0.0" ixz="0.0" iyy="8.016666666666669e-05" iyz="0.0" izz="5.416666666666668e-05"/>
    </inertial>
  </link>
  <!-- ****************** IMU SENSOR ***************************  -->
  <!-- imu joint -->
  <joint name="imu_joint" type="fixed">
    <parent link="case"/>
    <child link="imu"/>
    <origin rpy="0 0 0" xyz="-0.120 0.110 0.2475 "/>
  </joint>
  <!-- imu Link -->
  <link name="imu">
    <collision>
      <origin rpy="0 0 0" xyz="0 0 0"/>
      <geometry>
        <box size="0.036 0.036 0.015 "/>
      </geometry>
    </collision>
    <visual>
      <origin rpy="0 0 0" xyz="0 0 0"/>
      <geometry>
        <box size="0.036 0.036 0.015 "/>
      </geometry>
      <material name="red"/>
    </visual>
    <inertial>
      <origin rpy="0 0 0" xyz="0 0 0"/>
      <mass value="0.02"/>
      <inertia ixx="2.535e-06" ixy="0.0" ixz="0.0" iyy="2.535e-06" iyz="0.0" izz="4.32e-06"/>
    </inertial>
  </link>
  <!-- ****************** CAMERA SENSOR ***************************  -->
  <!-- camera joint -->
  <joint name="camera_joint" type="fixed">
    <parent link="case"/>
    <child link="camera"/>
    <origin rpy="0 0 0" xyz="0.110 0.0 0.1945 "/>
  </joint>
  <!-- camera Link -->
  <link name="camera">
    <collision>
      <origin rpy="0 0 0" xyz="0 0 0"/>
      <geometry>
        <box size="0.026 0.124 0.029 "/>
      </geometry>
    </collision>
    <visual>
      <origin rpy="0 0 0" xyz="0 0 0"/>
      <geometry>
        <box size="0.026 0.124 0.029 "/>
      </geometry>
      <material name="red"/>
    </visual>
    <inertial>
      <origin rpy="0 0 0" xyz="0 0 0"/>
      <mass value="0.12"/>
      <inertia ixx="0.00016217" ixy="0.0" ixz="0.0" iyy="1.5170000000000002e-05" iyz="0.0" izz="0.00016052000000000001"/>
    </inertial>
  </link>
  <joint name="camera_optical_joint" type="fixed">
    <origin rpy="-1.5707963267948966 0 -1.5707963267948966" xyz=" 0 0 0"/>
    <parent link="camera"/>
    <child link="camera_optical"/>
  </joint>
  <link name="camera_optical"/>
</robot>
<?xml version="1.0" ?>
<!-- =================================================================================== -->
<!-- |    This document was autogenerated by xacro from ./src/my_robot_description/urdf/my_robot.xacro | -->
<!-- |    EDITING THIS FILE BY HAND IS NOT RECOMMENDED                                 | -->
<!-- =================================================================================== -->
<robot name="my_robot">
  <!-- TODO : fix wheel inertia -->
  <!-- shaft Z offset referenced at the botton of the case -->
  <material name="white">
    <color rgba="0.8 0.8 0.8 1"/>
  </material>
  <material name="black">
    <color rgba="0.1 0.1 0.1 1"/>
  </material>
  <material name="red">
    <color rgba="0.8 0.1 0.1 1"/>
  </material>
  <!-- ****************** ROBOT BASE FOOTPRINT (Z=0, center of rotation) ***************************  -->
  <link name="base_footprint"/>
  <joint name="base_joint" type="fixed">
    <parent link="base_footprint"/>
    <child link="case"/>
    <origin rpy="0 0 0" xyz="-0.15 0 0.125"/>
  </joint>
  <!-- ********************** ROBOT CASE *********************************  -->
  <link name="case">
    <collision>
      <origin rpy="0 0 0" xyz="0 0 0"/>
      <geometry>
        <box size="0.44 0.36 0.16"/>
      </geometry>
    </collision>
    <visual>
      <origin rpy="0 0 0" xyz="0 0 0"/>
      <geometry>
        <box size="0.44 0.36 0.16"/>
      </geometry>
      <material name="white"/>
    </visual>
    <inertial>
      <origin rpy="0 0 0" xyz="0 0 0"/>
      <mass value="2.0"/>
      <inertia ixx="0.025866666666666666" ixy="0.0" ixz="0.0" iyy="0.036533333333333334" iyz="0.0" izz="0.05386666666666666"/>
    </inertial>
  </link>
  <!-- ****************** ROBOT WHEELS ***************************  -->
  <joint name="left_wheel_joint" type="continuous">
    <parent link="case"/>
    <child link="left_wheel"/>
    <origin rpy="0 0 0" xyz="0.15 0.265 -0.04"/>
    <axis xyz="0 1 0"/>
    <dynamics damping="0.2"/>
  </joint>
  <!-- left wheel Link -->
  <link name="left_wheel">
    <collision>
      <origin rpy="1.5707963267948966 0 0" xyz="0 0 0"/>
      <geometry>
        <cylinder length="0.05" radius="0.085"/>
      </geometry>
    </collision>
    <visual>
      <origin rpy="1.5707963267948966 0 0" xyz="0 0 0"/>
      <geometry>
        <cylinder length="0.05" radius="0.085"/>
      </geometry>
      <material name="black"/>
    </visual>
    <inertial>
      <origin rpy="0 0 0" xyz="0 0 0"/>
      <mass value="2.5"/>
      <inertia ixx="0.005036458333333334" ixy="0" ixz="0" iyy="0.009031250000000001" iyz="0" izz="0.005036458333333334"/>
    </inertial>
  </link>
  <joint name="right_wheel_joint" type="continuous">
    <parent link="case"/>
    <child link="right_wheel"/>
    <origin rpy="0 0 0" xyz="0.15 -0.265 -0.04"/>
    <axis xyz="0 1 0"/>
    <dynamics damping="0.2"/>
  </joint>
  <!-- right wheel Link -->
  <link name="right_wheel">
    <collision>
      <origin rpy="1.5707963267948966 0 0" xyz="0 0 0"/>
      <geometry>
        <cylinder length="0.05" radius="0.085"/>
      </geometry>
    </collision>
    <visual>
      <origin rpy="1.5707963267948966 0 0" xyz="0 0 0"/>
      <geometry>
        <cylinder length="0.05" radius="0.085"/>
      </geometry>
      <material name="black"/>
    </visual>
    <inertial>
      <origin rpy="0 0 0" xyz="0 0 0"/>
      <mass value="2.5"/>
      <inertia ixx="0.005036458333333334" ixy="0" ixz="0" iyy="0.009031250000000001" iyz="0" izz="0.005036458333333334"/>
    </inertial>
  </link>
  <joint name="caster_wheel_joint" type="fixed">
    <parent link="case"/>
    <child link="caster_wheel"/>
    <origin rpy="0 0 0" xyz="-0.15 0 -0.1"/>
  </joint>
  <!-- caster wheel Link -->
  <link name="caster_wheel">
    <collision>
      <origin rpy="0 0 0" xyz="0 0 0"/>
      <geometry>
        <sphere radius="0.025"/>
      </geometry>
    </collision>
    <visual>
      <origin rpy="0 0 0" xyz="0 0 0"/>
      <geometry>
        <sphere radius="0.025"/>
      </geometry>
      <material name="black"/>
    </visual>
    <inertial>
      <origin rpy="0 0 0" xyz="0 0 0"/>
      <mass value="0.1"/>
      <inertia ixx="2.500000000000001e-05" ixy="0.0" ixz="0.0" iyy="2.500000000000001e-05" iyz="0.0" izz="2.500000000000001e-05"/>
    </inertial>
  </link>
  <!-- ****************** LASER SENSOR ***************************  -->
  <!-- laser joint -->
  <joint name="laser_joint" type="fixed">
    <parent link="case"/>
    <child link="laser"/>
    <origin rpy="0 0 0" xyz="0.180 0.0 0.115 "/>
  </joint>
  <!-- laser Link -->
  <link name="laser">
    <collision>
      <origin rpy="0 0 0" xyz="0 0 0"/>
      <geometry>
        <box size="0.05 0.05 0.07 "/>
      </geometry>
    </collision>
    <visual>
      <origin rpy="0 0 0" xyz="0 0 0"/>
      <geometry>
        <box size="0.05 0.05 0.07 "/>
      </geometry>
      <material name="red"/>
    </visual>
    <inertial>
      <origin rpy="0 0 0" xyz="0 0 0"/>
      <mass value="0.13"/>
      <inertia ixx="8.016666666666669e-05" ixy="0.0" ixz="0.0" iyy="8.016666666666669e-05" iyz="0.0" izz="5.416666666666668e-05"/>
    </inertial>
  </link>
  <!-- ****************** IMU SENSOR ***************************  -->
  <!-- imu joint -->
  <joint name="imu_joint" type="fixed">
    <parent link="case"/>
    <child link="imu"/>
    <origin rpy="0 0 0" xyz="-0.120 0.110 0.2475 "/>
  </joint>
  <!-- imu Link -->
  <link name="imu">
    <collision>
      <origin rpy="0 0 0" xyz="0 0 0"/>
      <geometry>
        <box size="0.036 0.036 0.015 "/>
      </geometry>
    </collision>
    <visual>
      <origin rpy="0 0 0" xyz="0 0 0"/>
      <geometry>
        <box size="0.036 0.036 0.015 "/>
      </geometry>
      <material name="red"/>
    </visual>
    <inertial>
      <origin rpy="0 0 0" xyz="0 0 0"/>
      <mass value="0.02"/>
      <inertia ixx="2.535e-06" ixy="0.0" ixz="0.0" iyy="2.535e-06" iyz="0.0" izz="4.32e-06"/>
    </inertial>
  </link>
  <!-- ****************** CAMERA SENSOR ***************************  -->
  <!-- camera joint -->
  <joint name="camera_joint" type="fixed">
    <parent link="case"/>
    <child link="camera"/>
    <origin rpy="0 0 0" xyz="0.110 0.0 0.1945 "/>
  </joint>
  <!-- camera Link -->
  <link name="camera">
    <collision>
      <origin rpy="0 0 0" xyz="0 0 0"/>
      <geometry>
        <box size="0.026 0.124 0.029 "/>
      </geometry>
    </collision>
    <visual>
      <origin rpy="0 0 0" xyz="0 0 0"/>
      <geometry>
        <box size="0.026 0.124 0.029 "/>
      </geometry>
      <material name="red"/>
    </visual>
    <inertial>
      <origin rpy="0 0 0" xyz="0 0 0"/>
      <mass value="0.12"/>
      <inertia ixx="0.00016217" ixy="0.0" ixz="0.0" iyy="1.5170000000000002e-05" iyz="0.0" izz="0.00016052000000000001"/>
    </inertial>
  </link>
  <joint name="camera_optical_joint" type="fixed">
    <origin rpy="-1.5707963267948966 0 -1.5707963267948966" xyz=" 0 0 0"/>
    <parent link="camera"/>
    <child link="camera_optical"/>
  </joint>
  <link name="camera_optical"/>
</robot>
<?xml version="1.0" ?>
<!-- =================================================================================== -->
<!-- |    This document was autogenerated by xacro from ./src/my_robot_description/urdf/my_robot.xacro | -->
<!-- |    EDITING THIS FILE BY HAND IS NOT RECOMMENDED                                 | -->
<!-- =================================================================================== -->
<robot name="my_robot">
  <!-- TODO : fix wheel inertia -->
  <!-- shaft Z offset referenced at the botton of the case -->
  <material name="white">
    <color rgba="0.8 0.8 0.8 1"/>
  </material>
  <material name="black">
    <color rgba="0.1 0.1 0.1 1"/>
  </material>
  <material name="red">
    <color rgba="0.8 0.1 0.1 1"/>
  </material>
  <!-- ****************** ROBOT BASE FOOTPRINT (Z=0, center of rotation) ***************************  -->
  <link name="base_footprint"/>
  <joint name="base_joint" type="fixed">
    <parent link="base_footprint"/>
    <child link="base_link"/>
    <origin rpy="0 0 0" xyz="-0.15 0 0.125"/>
  </joint>
  <!-- ********************** ROBOT CASE *********************************  -->
  <link name="base_link">
    <collision>
      <origin rpy="0 0 0" xyz="0 0 0"/>
      <geometry>
        <box size="0.44 0.36 0.16"/>
      </geometry>
    </collision>
    <visual>
      <origin rpy="0 0 0" xyz="0 0 0"/>
      <geometry>
        <box size="0.44 0.36 0.16"/>
      </geometry>
      <material name="white"/>
    </visual>
    <inertial>
      <origin rpy="0 0 0" xyz="0 0 0"/>
      <mass value="2.0"/>
      <inertia ixx="0.025866666666666666" ixy="0.0" ixz="0.0" iyy="0.036533333333333334" iyz="0.0" izz="0.05386666666666666"/>
    </inertial>
  </link>
  <!-- ****************** ROBOT WHEELS ***************************  -->
  <joint name="left_wheel_joint" type="continuous">
    <parent link="base_link"/>
    <child link="left_wheel"/>
    <origin rpy="0 0 0" xyz="0.15 0.265 -0.04"/>
    <axis xyz="0 1 0"/>
    <dynamics damping="0.2"/>
  </joint>
  <!-- left wheel Link -->
  <link name="left_wheel">
    <collision>
      <origin rpy="1.5707963267948966 0 0" xyz="0 0 0"/>
      <geometry>
        <cylinder length="0.05" radius="0.085"/>
      </geometry>
    </collision>
    <visual>
      <origin rpy="1.5707963267948966 0 0" xyz="0 0 0"/>
      <geometry>
        <cylinder length="0.05" radius="0.085"/>
      </geometry>
      <material name="black"/>
    </visual>
    <inertial>
      <origin rpy="0 0 0" xyz="0 0 0"/>
      <mass value="2.5"/>
      <inertia ixx="0.005036458333333334" ixy="0" ixz="0" iyy="0.009031250000000001" iyz="0" izz="0.005036458333333334"/>
    </inertial>
  </link>
  <joint name="right_wheel_joint" type="continuous">
    <parent link="base_link"/>
    <child link="right_wheel"/>
    <origin rpy="0 0 0" xyz="0.15 -0.265 -0.04"/>
    <axis xyz="0 1 0"/>
    <dynamics damping="0.2"/>
  </joint>
  <!-- right wheel Link -->
  <link name="right_wheel">
    <collision>
      <origin rpy="1.5707963267948966 0 0" xyz="0 0 0"/>
      <geometry>
        <cylinder length="0.05" radius="0.085"/>
      </geometry>
    </collision>
    <visual>
      <origin rpy="1.5707963267948966 0 0" xyz="0 0 0"/>
      <geometry>
        <cylinder length="0.05" radius="0.085"/>
      </geometry>
      <material name="black"/>
    </visual>
    <inertial>
      <origin rpy="0 0 0" xyz="0 0 0"/>
      <mass value="2.5"/>
      <inertia ixx="0.005036458333333334" ixy="0" ixz="0" iyy="0.009031250000000001" iyz="0" izz="0.005036458333333334"/>
    </inertial>
  </link>
  <joint name="caster_wheel_joint" type="fixed">
    <parent link="base_link"/>
    <child link="caster_wheel"/>
    <origin rpy="0 0 0" xyz="-0.15 0 -0.1"/>
  </joint>
  <!-- caster wheel Link -->
  <link name="caster_wheel">
    <collision>
      <origin rpy="0 0 0" xyz="0 0 0"/>
      <geometry>
        <sphere radius="0.025"/>
      </geometry>
    </collision>
    <visual>
      <origin rpy="0 0 0" xyz="0 0 0"/>
      <geometry>
        <sphere radius="0.025"/>
      </geometry>
      <material name="black"/>
    </visual>
    <inertial>
      <origin rpy="0 0 0" xyz="0 0 0"/>
      <mass value="0.1"/>
      <inertia ixx="2.500000000000001e-05" ixy="0.0" ixz="0.0" iyy="2.500000000000001e-05" iyz="0.0" izz="2.500000000000001e-05"/>
    </inertial>
  </link>
  <!-- ****************** LASER SENSOR ***************************  -->
  <!-- laser joint -->
  <joint name="laser_joint" type="fixed">
    <parent link="base_link"/>
    <child link="laser"/>
    <origin rpy="0 0 0" xyz="0.180 0.0 0.115 "/>
  </joint>
  <!-- laser Link -->
  <link name="laser">
    <collision>
      <origin rpy="0 0 0" xyz="0 0 0"/>
      <geometry>
        <box size="0.05 0.05 0.07 "/>
      </geometry>
    </collision>
    <visual>
      <origin rpy="0 0 0" xyz="0 0 0"/>
      <geometry>
        <box size="0.05 0.05 0.07 "/>
      </geometry>
      <material name="red"/>
    </visual>
    <inertial>
      <origin rpy="0 0 0" xyz="0 0 0"/>
      <mass value="0.13"/>
      <inertia ixx="8.016666666666669e-05" ixy="0.0" ixz="0.0" iyy="8.016666666666669e-05" iyz="0.0" izz="5.416666666666668e-05"/>
    </inertial>
  </link>
  <!-- ****************** IMU SENSOR ***************************  -->
  <!-- imu joint -->
  <joint name="imu_joint" type="fixed">
    <parent link="base_link"/>
    <child link="imu"/>
    <origin rpy="0 0 0" xyz="-0.120 0.110 0.2475 "/>
  </joint>
  <!-- imu Link -->
  <link name="imu">
    <collision>
      <origin rpy="0 0 0" xyz="0 0 0"/>
      <geometry>
        <box size="0.036 0.036 0.015 "/>
      </geometry>
    </collision>
    <visual>
      <origin rpy="0 0 0" xyz="0 0 0"/>
      <geometry>
        <box size="0.036 0.036 0.015 "/>
      </geometry>
      <material name="red"/>
    </visual>
    <inertial>
      <origin rpy="0 0 0" xyz="0 0 0"/>
      <mass value="0.02"/>
      <inertia ixx="2.535e-06" ixy="0.0" ixz="0.0" iyy="2.535e-06" iyz="0.0" izz="4.32e-06"/>
    </inertial>
  </link>
  <!-- ****************** CAMERA SENSOR ***************************  -->
  <!-- camera joint -->
  <joint name="camera_joint" type="fixed">
    <parent link="base_link"/>
    <child link="camera"/>
    <origin rpy="0 0 0" xyz="0.110 0.0 0.1945 "/>
  </joint>
  <!-- camera Link -->
  <link name="camera">
    <collision>
      <origin rpy="0 0 0" xyz="0 0 0"/>
      <geometry>
        <box size="0.026 0.124 0.029 "/>
      </geometry>
    </collision>
    <visual>
      <origin rpy="0 0 0" xyz="0 0 0"/>
      <geometry>
        <box size="0.026 0.124 0.029 "/>
      </geometry>
      <material name="red"/>
    </visual>
    <inertial>
      <origin rpy="0 0 0" xyz="0 0 0"/>
      <mass value="0.12"/>
      <inertia ixx="0.00016217" ixy="0.0" ixz="0.0" iyy="1.5170000000000002e-05" iyz="0.0" izz="0.00016052000000000001"/>
    </inertial>
  </link>
  <joint name="camera_optical_joint" type="fixed">
    <origin rpy="-1.5707963267948966 0 -1.5707963267948966" xyz=" 0 0 0"/>
    <parent link="camera"/>
    <child link="camera_optical"/>
  </joint>
  <link name="camera_optical"/>
</robot>
<?xml version="1.0" ?>
<!-- =================================================================================== -->
<!-- |    This document was autogenerated by xacro from ./src/my_robot_description/urdf/my_robot.xacro | -->
<!-- |    EDITING THIS FILE BY HAND IS NOT RECOMMENDED                                 | -->
<!-- =================================================================================== -->
<robot name="my_robot">
  <!-- TODO : fix wheel inertia -->
  <!-- shaft Z offset referenced at the botton of the case -->
  <material name="white">
    <color rgba="0.8 0.8 0.8 1"/>
  </material>
  <material name="black">
    <color rgba="0.1 0.1 0.1 1"/>
  </material>
  <material name="red">
    <color rgba="0.8 0.1 0.1 1"/>
  </material>
  <!-- ****************** ROBOT BASE FOOTPRINT (Z=0, center of rotation) ***************************  -->
  <link name="base_footprint"/>
  <joint name="base_joint" type="fixed">
    <parent link="base_footprint"/>
    <child link="base_link"/>
    <origin rpy="0 0 0" xyz="-0.15 0 0.125"/>
  </joint>
  <!-- ********************** ROBOT CASE *********************************  -->
  <link name="base_link">
    <collision>
      <origin rpy="0 0 0" xyz="0 0 0"/>
      <geometry>
        <box size="0.44 0.36 0.16"/>
      </geometry>
    </collision>
    <visual>
      <origin rpy="0 0 0" xyz="0 0 0"/>
      <geometry>
        <box size="0.44 0.36 0.16"/>
      </geometry>
      <material name="white"/>
    </visual>
    <inertial>
      <origin rpy="0 0 0" xyz="0 0 0"/>
      <mass value="2.0"/>
      <inertia ixx="0.025866666666666666" ixy="0.0" ixz="0.0" iyy="0.036533333333333334" iyz="0.0" izz="0.05386666666666666"/>
    </inertial>
  </link>
  <!-- ****************** ROBOT WHEELS ***************************  -->
  <joint name="left_wheel_joint" type="continuous">
    <parent link="base_link"/>
    <child link="left_wheel"/>
    <origin rpy="0 0 0" xyz="0.15 0.265 -0.04"/>
    <axis xyz="0 1 0"/>
    <dynamics damping="0.2"/>
  </joint>
  <!-- left wheel Link -->
  <link name="left_wheel">
    <collision>
      <origin rpy="1.5707963267948966 0 0" xyz="0 0 0"/>
      <geometry>
        <cylinder length="0.05" radius="0.085"/>
      </geometry>
    </collision>
    <visual>
      <origin rpy="1.5707963267948966 0 0" xyz="0 0 0"/>
      <geometry>
        <cylinder length="0.05" radius="0.085"/>
      </geometry>
      <material name="black"/>
    </visual>
    <inertial>
      <origin rpy="0 0 0" xyz="0 0 0"/>
      <mass value="2.5"/>
      <inertia ixx="0.005036458333333334" ixy="0" ixz="0" iyy="0.009031250000000001" iyz="0" izz="0.005036458333333334"/>
    </inertial>
  </link>
  <joint name="right_wheel_joint" type="continuous">
    <parent link="base_link"/>
    <child link="right_wheel"/>
    <origin rpy="0 0 0" xyz="0.15 -0.265 -0.04"/>
    <axis xyz="0 1 0"/>
    <dynamics damping="0.2"/>
  </joint>
  <!-- right wheel Link -->
  <link name="right_wheel">
    <collision>
      <origin rpy="1.5707963267948966 0 0" xyz="0 0 0"/>
      <geometry>
        <cylinder length="0.05" radius="0.085"/>
      </geometry>
    </collision>
    <visual>
      <origin rpy="1.5707963267948966 0 0" xyz="0 0 0"/>
      <geometry>
        <cylinder length="0.05" radius="0.085"/>
      </geometry>
      <material name="black"/>
    </visual>
    <inertial>
      <origin rpy="0 0 0" xyz="0 0 0"/>
      <mass value="2.5"/>
      <inertia ixx="0.005036458333333334" ixy="0" ixz="0" iyy="0.009031250000000001" iyz="0" izz="0.005036458333333334"/>
    </inertial>
  </link>
  <joint name="caster_wheel_joint" type="fixed">
    <parent link="base_link"/>
    <child link="caster_wheel"/>
    <origin rpy="0 0 0" xyz="-0.15 0 -0.1"/>
  </joint>
  <!-- caster wheel Link -->
  <link name="caster_wheel">
    <collision>
      <origin rpy="0 0 0" xyz="0 0 0"/>
      <geometry>
        <sphere radius="0.025"/>
      </geometry>
    </collision>
    <visual>
      <origin rpy="0 0 0" xyz="0 0 0"/>
      <geometry>
        <sphere radius="0.025"/>
      </geometry>
      <material name="black"/>
    </visual>
    <inertial>
      <origin rpy="0 0 0" xyz="0 0 0"/>
      <mass value="0.1"/>
      <inertia ixx="2.500000000000001e-05" ixy="0.0" ixz="0.0" iyy="2.500000000000001e-05" iyz="0.0" izz="2.500000000000001e-05"/>
    </inertial>
  </link>
  <!-- ****************** LASER SENSOR ***************************  -->
  <!-- laser joint -->
  <joint name="laser_joint" type="fixed">
    <parent link="base_link"/>
    <child link="laser"/>
    <origin rpy="0 0 0" xyz="0.180 0.0 0.115 "/>
  </joint>
  <!-- laser Link -->
  <link name="laser">
    <collision>
      <origin rpy="0 0 0" xyz="0 0 0"/>
      <geometry>
        <box size="0.05 0.05 0.07 "/>
      </geometry>
    </collision>
    <visual>
      <origin rpy="0 0 0" xyz="0 0 0"/>
      <geometry>
        <box size="0.05 0.05 0.07 "/>
      </geometry>
      <material name="red"/>
    </visual>
    <inertial>
      <origin rpy="0 0 0" xyz="0 0 0"/>
      <mass value="0.13"/>
      <inertia ixx="8.016666666666669e-05" ixy="0.0" ixz="0.0" iyy="8.016666666666669e-05" iyz="0.0" izz="5.416666666666668e-05"/>
    </inertial>
  </link>
  <!-- ****************** IMU SENSOR ***************************  -->
  <!-- imu joint -->
  <joint name="imu_joint" type="fixed">
    <parent link="base_link"/>
    <child link="imu"/>
    <origin rpy="0 0 0" xyz="-0.120 0.110 0.2475 "/>
  </joint>
  <!-- imu Link -->
  <link name="imu">
    <collision>
      <origin rpy="0 0 0" xyz="0 0 0"/>
      <geometry>
        <box size="0.036 0.036 0.015 "/>
      </geometry>
    </collision>
    <visual>
      <origin rpy="0 0 0" xyz="0 0 0"/>
      <geometry>
        <box size="0.036 0.036 0.015 "/>
      </geometry>
      <material name="red"/>
    </visual>
    <inertial>
      <origin rpy="0 0 0" xyz="0 0 0"/>
      <mass value="0.02"/>
      <inertia ixx="2.535e-06" ixy="0.0" ixz="0.0" iyy="2.535e-06" iyz="0.0" izz="4.32e-06"/>
    </inertial>
  </link>
  <!-- ****************** CAMERA SENSOR ***************************  -->
  <!-- camera joint -->
  <joint name="camera_joint" type="fixed">
    <parent link="base_link"/>
    <child link="camera"/>
    <origin rpy="0 0 0" xyz="0.110 0.0 0.1945 "/>
  </joint>
  <!-- camera Link -->
  <link name="camera">
    <collision>
      <origin rpy="0 0 0" xyz="0 0 0"/>
      <geometry>
        <box size="0.026 0.124 0.029 "/>
      </geometry>
    </collision>
    <visual>
      <origin rpy="0 0 0" xyz="0 0 0"/>
      <geometry>
        <box size="0.026 0.124 0.029 "/>
      </geometry>
      <material name="red"/>
    </visual>
    <inertial>
      <origin rpy="0 0 0" xyz="0 0 0"/>
      <mass value="0.12"/>
      <inertia ixx="0.00016217" ixy="0.0" ixz="0.0" iyy="1.5170000000000002e-05" iyz="0.0" izz="0.00016052000000000001"/>
    </inertial>
  </link>
  <joint name="camera_optical_joint" type="fixed">
    <origin rpy="-1.5707963267948966 0 -1.5707963267948966" xyz=" 0 0 0"/>
    <parent link="camera"/>
    <child link="camera_optical"/>
  </joint>
  <link name="camera_optical"/>
</robot>
